I'm sorry, but an uncaught exception occurred.

While running game code:
  File "game/script.rpy", line 25, in script
    define config.say_arguments_callback = log_callback
  File "game/script.rpy", line 25, in <module>
    define config.say_arguments_callback = log_callback
NameError: name 'log_callback' is not defined

-- Full Traceback ------------------------------------------------------------

Full traceback:
  File "game/script.rpy", line 25, in script
    define config.say_arguments_callback = log_callback
  File "/Users/nichosantos/Documents/[CODING]/renpy-8.2.3-sdk/renpy/ast.py", line 2248, in execute
    self.set()
  File "/Users/nichosantos/Documents/[CODING]/renpy-8.2.3-sdk/renpy/ast.py", line 2262, in set
    value = renpy.python.py_eval_bytecode(self.code.bytecode)
  File "/Users/nichosantos/Documents/[CODING]/renpy-8.2.3-sdk/renpy/python.py", line 1211, in py_eval_bytecode
    return eval(bytecode, globals, locals)
  File "game/script.rpy", line 25, in <module>
    define config.say_arguments_callback = log_callback
NameError: name 'log_callback' is not defined

macOS-13.4-arm64-arm-64bit arm64
Ren'Py 8.3.7.25031702
PLEASE IM BEGGING YOU 1.0
Sat May  3 15:29:42 2025
