I'm sorry, but an uncaught exception occurred.

While running game code:
  File "game/03_minerva_f2f.rpy", line 250, in script
    dm "oh, joy. yeah i’ve been awake."
Exception: Sayer 'dm' is not defined.

-- Full Traceback ------------------------------------------------------------

Full traceback:
  File "game/03_minerva_f2f.rpy", line 250, in script
    dm "oh, joy. yeah i’ve been awake."
  File "/Users/nichosantos/Documents/[CODING]/renpy-8.2.3-sdk/renpy/ast.py", line 2586, in execute
    Say.execute(self)
  File "/Users/nichosantos/Documents/[CODING]/renpy-8.2.3-sdk/renpy/ast.py", line 583, in execute
    who = eval_who(self.who, self.who_fast)
  File "/Users/nichosantos/Documents/[CODING]/renpy-8.2.3-sdk/renpy/ast.py", line 472, in eval_who
    raise Exception("Sayer '%s' is not defined." % who)
Exception: Sayer 'dm' is not defined.

macOS-13.4-arm64-arm-64bit arm64
Ren'Py 8.3.7.25031702
PLEASE IM BEGGING YOU 1.0
Sat May  3 15:53:32 2025
