I'm sorry, but an uncaught exception occurred.

While running game code:
  File "game/script.rpy", line 49, in script
    bug "hey i'm testing this still"
Exception: Sayer 'bug' is not defined.

-- Full Traceback ------------------------------------------------------------

Full traceback:
  File "game/script.rpy", line 49, in script
    bug "hey i'm testing this still"
  File "/Users/nichosantos/Documents/[CODING]/renpy-8.2.3-sdk/renpy/ast.py", line 2586, in execute
    Say.execute(self)
  File "/Users/nichosantos/Documents/[CODING]/renpy-8.2.3-sdk/renpy/ast.py", line 583, in execute
    who = eval_who(self.who, self.who_fast)
  File "/Users/nichosantos/Documents/[CODING]/renpy-8.2.3-sdk/renpy/ast.py", line 472, in eval_who
    raise Exception("Sayer '%s' is not defined." % who)
Exception: Sayer 'bug' is not defined.

macOS-13.4-arm64-arm-64bit arm64
Ren'Py 8.3.7.25031702
PLEASE IM BEGGING YOU 1.0
Mon May  5 02:02:28 2025
